2017-08-30 04:13:26.058048: Error occurred while reading WSGI handler:

Traceback (most recent call last):
  File "C:\Python34\Scripts\wfastcgi.py", line 711, in main
    env, handler = read_wsgi_handler(response.physical_path)
  File "C:\Python34\Scripts\wfastcgi.py", line 568, in read_wsgi_handler
    return env, get_wsgi_handler(handler_name)
  File "C:\Python34\Scripts\wfastcgi.py", line 551, in get_wsgi_handler
    raise ValueError('"%s" could not be imported' % handler_name)
ValueError: "django.core.handlers.wsgi.WSGIHandler()" could not be imported


StdOut: 

StdErr: 
2017-08-30 04:13:26.062057: Unhandled exception in wfastcgi.py: Traceback (most recent call last):
  File "C:\Python34\Scripts\wfastcgi.py", line 711, in main
    env, handler = read_wsgi_handler(response.physical_path)
  File "C:\Python34\Scripts\wfastcgi.py", line 568, in read_wsgi_handler
    return env, get_wsgi_handler(handler_name)
  File "C:\Python34\Scripts\wfastcgi.py", line 551, in get_wsgi_handler
    raise ValueError('"%s" could not be imported' % handler_name)
ValueError: "django.core.handlers.wsgi.WSGIHandler()" could not be imported
2017-08-30 04:13:26.070078: wfastcgi.py 2.1.1 closed
2017-08-30 04:13:28.150199: Error occurred while reading WSGI handler:

Traceback (most recent call last):
  File "C:\Python34\Scripts\wfastcgi.py", line 711, in main
    env, handler = read_wsgi_handler(response.physical_path)
  File "C:\Python34\Scripts\wfastcgi.py", line 568, in read_wsgi_handler
    return env, get_wsgi_handler(handler_name)
  File "C:\Python34\Scripts\wfastcgi.py", line 551, in get_wsgi_handler
    raise ValueError('"%s" could not be imported' % handler_name)
ValueError: "django.core.handlers.wsgi.WSGIHandler()" could not be imported


StdOut: 

StdErr: 
2017-08-30 04:13:28.154175: Unhandled exception in wfastcgi.py: Traceback (most recent call last):
  File "C:\Python34\Scripts\wfastcgi.py", line 711, in main
    env, handler = read_wsgi_handler(response.physical_path)
  File "C:\Python34\Scripts\wfastcgi.py", line 568, in read_wsgi_handler
    return env, get_wsgi_handler(handler_name)
  File "C:\Python34\Scripts\wfastcgi.py", line 551, in get_wsgi_handler
    raise ValueError('"%s" could not be imported' % handler_name)
ValueError: "django.core.handlers.wsgi.WSGIHandler()" could not be imported
2017-08-30 04:13:28.159188: wfastcgi.py 2.1.1 closed
2017-08-30 04:14:02.702858: Error occurred while reading WSGI handler:

Traceback (most recent call last):
  File "C:\Python34\Scripts\wfastcgi.py", line 711, in main
    env, handler = read_wsgi_handler(response.physical_path)
  File "C:\Python34\Scripts\wfastcgi.py", line 568, in read_wsgi_handler
    return env, get_wsgi_handler(handler_name)
  File "C:\Python34\Scripts\wfastcgi.py", line 551, in get_wsgi_handler
    raise ValueError('"%s" could not be imported' % handler_name)
ValueError: "C:\Python34\Scripts\wfastcgi.py" could not be imported


StdOut: 

StdErr: 
2017-08-30 04:14:02.706870: Unhandled exception in wfastcgi.py: Traceback (most recent call last):
  File "C:\Python34\Scripts\wfastcgi.py", line 711, in main
    env, handler = read_wsgi_handler(response.physical_path)
  File "C:\Python34\Scripts\wfastcgi.py", line 568, in read_wsgi_handler
    return env, get_wsgi_handler(handler_name)
  File "C:\Python34\Scripts\wfastcgi.py", line 551, in get_wsgi_handler
    raise ValueError('"%s" could not be imported' % handler_name)
ValueError: "C:\Python34\Scripts\wfastcgi.py" could not be imported
2017-08-30 04:14:02.711883: wfastcgi.py 2.1.1 closed
2017-08-30 04:14:03.228002: Error occurred while reading WSGI handler:

Traceback (most recent call last):
  File "C:\Python34\Scripts\wfastcgi.py", line 711, in main
    env, handler = read_wsgi_handler(response.physical_path)
  File "C:\Python34\Scripts\wfastcgi.py", line 568, in read_wsgi_handler
    return env, get_wsgi_handler(handler_name)
  File "C:\Python34\Scripts\wfastcgi.py", line 551, in get_wsgi_handler
    raise ValueError('"%s" could not be imported' % handler_name)
ValueError: "C:\Python34\Scripts\wfastcgi.py" could not be imported


StdOut: 

StdErr: 
2017-08-30 04:14:03.231011: Unhandled exception in wfastcgi.py: Traceback (most recent call last):
  File "C:\Python34\Scripts\wfastcgi.py", line 711, in main
    env, handler = read_wsgi_handler(response.physical_path)
  File "C:\Python34\Scripts\wfastcgi.py", line 568, in read_wsgi_handler
    return env, get_wsgi_handler(handler_name)
  File "C:\Python34\Scripts\wfastcgi.py", line 551, in get_wsgi_handler
    raise ValueError('"%s" could not be imported' % handler_name)
ValueError: "C:\Python34\Scripts\wfastcgi.py" could not be imported
2017-08-30 04:14:03.236024: wfastcgi.py 2.1.1 closed
2017-08-30 04:14:03.489194: Error occurred while reading WSGI handler:

Traceback (most recent call last):
  File "C:\Python34\Scripts\wfastcgi.py", line 711, in main
    env, handler = read_wsgi_handler(response.physical_path)
  File "C:\Python34\Scripts\wfastcgi.py", line 568, in read_wsgi_handler
    return env, get_wsgi_handler(handler_name)
  File "C:\Python34\Scripts\wfastcgi.py", line 551, in get_wsgi_handler
    raise ValueError('"%s" could not be imported' % handler_name)
ValueError: "C:\Python34\Scripts\wfastcgi.py" could not be imported


StdOut: 

StdErr: 
2017-08-30 04:14:03.493204: Unhandled exception in wfastcgi.py: Traceback (most recent call last):
  File "C:\Python34\Scripts\wfastcgi.py", line 711, in main
    env, handler = read_wsgi_handler(response.physical_path)
  File "C:\Python34\Scripts\wfastcgi.py", line 568, in read_wsgi_handler
    return env, get_wsgi_handler(handler_name)
  File "C:\Python34\Scripts\wfastcgi.py", line 551, in get_wsgi_handler
    raise ValueError('"%s" could not be imported' % handler_name)
ValueError: "C:\Python34\Scripts\wfastcgi.py" could not be imported
2017-08-30 04:14:03.498252: wfastcgi.py 2.1.1 closed
2017-08-30 04:14:03.678738: Error occurred while reading WSGI handler:

Traceback (most recent call last):
  File "C:\Python34\Scripts\wfastcgi.py", line 711, in main
    env, handler = read_wsgi_handler(response.physical_path)
  File "C:\Python34\Scripts\wfastcgi.py", line 568, in read_wsgi_handler
    return env, get_wsgi_handler(handler_name)
  File "C:\Python34\Scripts\wfastcgi.py", line 551, in get_wsgi_handler
    raise ValueError('"%s" could not be imported' % handler_name)
ValueError: "C:\Python34\Scripts\wfastcgi.py" could not be imported


StdOut: 

StdErr: 
2017-08-30 04:14:03.682747: Unhandled exception in wfastcgi.py: Traceback (most recent call last):
  File "C:\Python34\Scripts\wfastcgi.py", line 711, in main
    env, handler = read_wsgi_handler(response.physical_path)
  File "C:\Python34\Scripts\wfastcgi.py", line 568, in read_wsgi_handler
    return env, get_wsgi_handler(handler_name)
  File "C:\Python34\Scripts\wfastcgi.py", line 551, in get_wsgi_handler
    raise ValueError('"%s" could not be imported' % handler_name)
ValueError: "C:\Python34\Scripts\wfastcgi.py" could not be imported
2017-08-30 04:14:03.687761: wfastcgi.py 2.1.1 closed
2017-08-30 04:14:04.311989: Error occurred while reading WSGI handler:

Traceback (most recent call last):
  File "C:\Python34\Scripts\wfastcgi.py", line 711, in main
    env, handler = read_wsgi_handler(response.physical_path)
  File "C:\Python34\Scripts\wfastcgi.py", line 568, in read_wsgi_handler
    return env, get_wsgi_handler(handler_name)
  File "C:\Python34\Scripts\wfastcgi.py", line 551, in get_wsgi_handler
    raise ValueError('"%s" could not be imported' % handler_name)
ValueError: "C:\Python34\Scripts\wfastcgi.py" could not be imported


StdOut: 

StdErr: 
2017-08-30 04:14:04.316001: Unhandled exception in wfastcgi.py: Traceback (most recent call last):
  File "C:\Python34\Scripts\wfastcgi.py", line 711, in main
    env, handler = read_wsgi_handler(response.physical_path)
  File "C:\Python34\Scripts\wfastcgi.py", line 568, in read_wsgi_handler
    return env, get_wsgi_handler(handler_name)
  File "C:\Python34\Scripts\wfastcgi.py", line 551, in get_wsgi_handler
    raise ValueError('"%s" could not be imported' % handler_name)
ValueError: "C:\Python34\Scripts\wfastcgi.py" could not be imported
2017-08-30 04:14:04.320014: wfastcgi.py 2.1.1 closed
2017-08-30 04:14:05.021306: Error occurred while reading WSGI handler:

Traceback (most recent call last):
  File "C:\Python34\Scripts\wfastcgi.py", line 711, in main
    env, handler = read_wsgi_handler(response.physical_path)
  File "C:\Python34\Scripts\wfastcgi.py", line 568, in read_wsgi_handler
    return env, get_wsgi_handler(handler_name)
  File "C:\Python34\Scripts\wfastcgi.py", line 551, in get_wsgi_handler
    raise ValueError('"%s" could not be imported' % handler_name)
ValueError: "C:\Python34\Scripts\wfastcgi.py" could not be imported


StdOut: 

StdErr: 
2017-08-30 04:14:05.024313: Unhandled exception in wfastcgi.py: Traceback (most recent call last):
  File "C:\Python34\Scripts\wfastcgi.py", line 711, in main
    env, handler = read_wsgi_handler(response.physical_path)
  File "C:\Python34\Scripts\wfastcgi.py", line 568, in read_wsgi_handler
    return env, get_wsgi_handler(handler_name)
  File "C:\Python34\Scripts\wfastcgi.py", line 551, in get_wsgi_handler
    raise ValueError('"%s" could not be imported' % handler_name)
ValueError: "C:\Python34\Scripts\wfastcgi.py" could not be imported
2017-08-30 04:14:05.030329: wfastcgi.py 2.1.1 closed
2017-08-30 04:14:08.876034: Error occurred while reading WSGI handler:

Traceback (most recent call last):
  File "C:\Python34\Scripts\wfastcgi.py", line 711, in main
    env, handler = read_wsgi_handler(response.physical_path)
  File "C:\Python34\Scripts\wfastcgi.py", line 568, in read_wsgi_handler
    return env, get_wsgi_handler(handler_name)
  File "C:\Python34\Scripts\wfastcgi.py", line 551, in get_wsgi_handler
    raise ValueError('"%s" could not be imported' % handler_name)
ValueError: "C:\Python34\Scripts\wfastcgi.py" could not be imported


StdOut: 

StdErr: 
2017-08-30 04:14:08.879075: Unhandled exception in wfastcgi.py: Traceback (most recent call last):
  File "C:\Python34\Scripts\wfastcgi.py", line 711, in main
    env, handler = read_wsgi_handler(response.physical_path)
  File "C:\Python34\Scripts\wfastcgi.py", line 568, in read_wsgi_handler
    return env, get_wsgi_handler(handler_name)
  File "C:\Python34\Scripts\wfastcgi.py", line 551, in get_wsgi_handler
    raise ValueError('"%s" could not be imported' % handler_name)
ValueError: "C:\Python34\Scripts\wfastcgi.py" could not be imported
2017-08-30 04:14:08.886062: wfastcgi.py 2.1.1 closed
2017-08-30 04:14:09.330502: Error occurred while reading WSGI handler:

Traceback (most recent call last):
  File "C:\Python34\Scripts\wfastcgi.py", line 711, in main
    env, handler = read_wsgi_handler(response.physical_path)
  File "C:\Python34\Scripts\wfastcgi.py", line 568, in read_wsgi_handler
    return env, get_wsgi_handler(handler_name)
  File "C:\Python34\Scripts\wfastcgi.py", line 551, in get_wsgi_handler
    raise ValueError('"%s" could not be imported' % handler_name)
ValueError: "C:\Python34\Scripts\wfastcgi.py" could not be imported


StdOut: 

StdErr: 
2017-08-30 04:14:09.334510: Unhandled exception in wfastcgi.py: Traceback (most recent call last):
  File "C:\Python34\Scripts\wfastcgi.py", line 711, in main
    env, handler = read_wsgi_handler(response.physical_path)
  File "C:\Python34\Scripts\wfastcgi.py", line 568, in read_wsgi_handler
    return env, get_wsgi_handler(handler_name)
  File "C:\Python34\Scripts\wfastcgi.py", line 551, in get_wsgi_handler
    raise ValueError('"%s" could not be imported' % handler_name)
ValueError: "C:\Python34\Scripts\wfastcgi.py" could not be imported
2017-08-30 04:14:09.340527: wfastcgi.py 2.1.1 closed
2017-08-30 04:14:59.597737: Error occurred while reading WSGI handler:

Traceback (most recent call last):
  File "C:\Python34\Scripts\wfastcgi.py", line 711, in main
    env, handler = read_wsgi_handler(response.physical_path)
  File "C:\Python34\Scripts\wfastcgi.py", line 568, in read_wsgi_handler
    return env, get_wsgi_handler(handler_name)
  File "C:\Python34\Scripts\wfastcgi.py", line 551, in get_wsgi_handler
    raise ValueError('"%s" could not be imported' % handler_name)
ValueError: "C:\Users\vlab\Desktop\GPA_Server\GPAv2\wsgi.py" could not be imported


StdOut: 

StdErr: 
2017-08-30 04:14:59.602750: Unhandled exception in wfastcgi.py: Traceback (most recent call last):
  File "C:\Python34\Scripts\wfastcgi.py", line 711, in main
    env, handler = read_wsgi_handler(response.physical_path)
  File "C:\Python34\Scripts\wfastcgi.py", line 568, in read_wsgi_handler
    return env, get_wsgi_handler(handler_name)
  File "C:\Python34\Scripts\wfastcgi.py", line 551, in get_wsgi_handler
    raise ValueError('"%s" could not be imported' % handler_name)
ValueError: "C:\Users\vlab\Desktop\GPA_Server\GPAv2\wsgi.py" could not be imported
2017-08-30 04:14:59.608768: wfastcgi.py 2.1.1 closed
2017-08-30 04:26:14.630152: Error occurred while reading WSGI handler:

Traceback (most recent call last):
  File "C:\Python34\Scripts\wfastcgi.py", line 711, in main
    env, handler = read_wsgi_handler(response.physical_path)
  File "C:\Python34\Scripts\wfastcgi.py", line 568, in read_wsgi_handler
    return env, get_wsgi_handler(handler_name)
  File "C:\Python34\Scripts\wfastcgi.py", line 551, in get_wsgi_handler
    raise ValueError('"%s" could not be imported' % handler_name)
ValueError: "C:\Users\vlab\Desktop\GPA_Server\GPAv2\wsgi.py" could not be imported


StdOut: 

StdErr: 
2017-08-30 04:26:14.634164: Unhandled exception in wfastcgi.py: Traceback (most recent call last):
  File "C:\Python34\Scripts\wfastcgi.py", line 711, in main
    env, handler = read_wsgi_handler(response.physical_path)
  File "C:\Python34\Scripts\wfastcgi.py", line 568, in read_wsgi_handler
    return env, get_wsgi_handler(handler_name)
  File "C:\Python34\Scripts\wfastcgi.py", line 551, in get_wsgi_handler
    raise ValueError('"%s" could not be imported' % handler_name)
ValueError: "C:\Users\vlab\Desktop\GPA_Server\GPAv2\wsgi.py" could not be imported
2017-08-30 04:26:14.639176: wfastcgi.py 2.1.1 closed
2017-08-30 04:26:15.570889: Error occurred while reading WSGI handler:

Traceback (most recent call last):
  File "C:\Python34\Scripts\wfastcgi.py", line 711, in main
    env, handler = read_wsgi_handler(response.physical_path)
  File "C:\Python34\Scripts\wfastcgi.py", line 568, in read_wsgi_handler
    return env, get_wsgi_handler(handler_name)
  File "C:\Python34\Scripts\wfastcgi.py", line 551, in get_wsgi_handler
    raise ValueError('"%s" could not be imported' % handler_name)
ValueError: "C:\Users\vlab\Desktop\GPA_Server\GPAv2\wsgi.py" could not be imported


StdOut: 

StdErr: 
2017-08-30 04:26:15.573898: Unhandled exception in wfastcgi.py: Traceback (most recent call last):
  File "C:\Python34\Scripts\wfastcgi.py", line 711, in main
    env, handler = read_wsgi_handler(response.physical_path)
  File "C:\Python34\Scripts\wfastcgi.py", line 568, in read_wsgi_handler
    return env, get_wsgi_handler(handler_name)
  File "C:\Python34\Scripts\wfastcgi.py", line 551, in get_wsgi_handler
    raise ValueError('"%s" could not be imported' % handler_name)
ValueError: "C:\Users\vlab\Desktop\GPA_Server\GPAv2\wsgi.py" could not be imported
2017-08-30 04:26:15.578911: wfastcgi.py 2.1.1 closed
2017-08-30 04:30:54.504901: Error occurred while reading WSGI handler:

Traceback (most recent call last):
  File "c:\users\vlab\appdata\local\programs\python\python35\lib\site-packages\wfastcgi.py", line 791, in main
    env, handler = read_wsgi_handler(response.physical_path)
  File "c:\users\vlab\appdata\local\programs\python\python35\lib\site-packages\wfastcgi.py", line 633, in read_wsgi_handler
    handler = get_wsgi_handler(os.getenv("WSGI_HANDLER"))
  File "c:\users\vlab\appdata\local\programs\python\python35\lib\site-packages\wfastcgi.py", line 616, in get_wsgi_handler
    raise ValueError('"%s" could not be imported%s' % (handler_name, last_tb))
ValueError: "C:\Users\vlab\Desktop\GPA_Server\GPAv2\wsgi.py" could not be imported: Traceback (most recent call last):
  File "c:\users\vlab\appdata\local\programs\python\python35\lib\site-packages\wfastcgi.py", line 600, in get_wsgi_handler
    handler = __import__(module_name, fromlist=[name_list[0][0]])
ImportError: No module named 'C:\\Users\\vlab\\Desktop\\GPA_Server\\GPAv2\\wsgi'



StdOut: 

StdErr: 
2017-08-30 04:30:54.508919: Unhandled exception in wfastcgi.py: Traceback (most recent call last):
  File "c:\users\vlab\appdata\local\programs\python\python35\lib\site-packages\wfastcgi.py", line 791, in main
    env, handler = read_wsgi_handler(response.physical_path)
  File "c:\users\vlab\appdata\local\programs\python\python35\lib\site-packages\wfastcgi.py", line 633, in read_wsgi_handler
    handler = get_wsgi_handler(os.getenv("WSGI_HANDLER"))
  File "c:\users\vlab\appdata\local\programs\python\python35\lib\site-packages\wfastcgi.py", line 616, in get_wsgi_handler
    raise ValueError('"%s" could not be imported%s' % (handler_name, last_tb))
ValueError: "C:\Users\vlab\Desktop\GPA_Server\GPAv2\wsgi.py" could not be imported: Traceback (most recent call last):
  File "c:\users\vlab\appdata\local\programs\python\python35\lib\site-packages\wfastcgi.py", line 600, in get_wsgi_handler
    handler = __import__(module_name, fromlist=[name_list[0][0]])
ImportError: No module named 'C:\\Users\\vlab\\Desktop\\GPA_Server\\GPAv2\\wsgi'

2017-08-30 04:30:54.513927: Running on_exit tasks
2017-08-30 04:30:54.519942: wfastcgi.py 3.0.0 closed
2017-08-30 04:31:17.504847: Error occurred while reading WSGI handler:

Traceback (most recent call last):
  File "c:\users\vlab\appdata\local\programs\python\python35\lib\site-packages\wfastcgi.py", line 791, in main
    env, handler = read_wsgi_handler(response.physical_path)
  File "c:\users\vlab\appdata\local\programs\python\python35\lib\site-packages\wfastcgi.py", line 633, in read_wsgi_handler
    handler = get_wsgi_handler(os.getenv("WSGI_HANDLER"))
  File "c:\users\vlab\appdata\local\programs\python\python35\lib\site-packages\wfastcgi.py", line 605, in get_wsgi_handler
    handler = handler()
  File "c:\users\vlab\appdata\local\programs\python\python35\lib\site-packages\django\core\handlers\wsgi.py", line 151, in __init__
    self.load_middleware()
  File "c:\users\vlab\appdata\local\programs\python\python35\lib\site-packages\django\core\handlers\base.py", line 80, in load_middleware
    middleware = import_string(middleware_path)
  File "c:\users\vlab\appdata\local\programs\python\python35\lib\site-packages\django\utils\module_loading.py", line 20, in import_string
    module = import_module(module_path)
  File "c:\users\vlab\appdata\local\programs\python\python35\lib\importlib\__init__.py", line 126, in import_module
    return _bootstrap._gcd_import(name[level:], package, level)
  File "<frozen importlib._bootstrap>", line 986, in _gcd_import
  File "<frozen importlib._bootstrap>", line 969, in _find_and_load
  File "<frozen importlib._bootstrap>", line 958, in _find_and_load_unlocked
  File "<frozen importlib._bootstrap>", line 673, in _load_unlocked
  File "<frozen importlib._bootstrap_external>", line 673, in exec_module
  File "<frozen importlib._bootstrap>", line 222, in _call_with_frames_removed
  File "c:\users\vlab\appdata\local\programs\python\python35\lib\site-packages\django\contrib\auth\middleware.py", line 4, in <module>
    from django.contrib.auth.backends import RemoteUserBackend
  File "c:\users\vlab\appdata\local\programs\python\python35\lib\site-packages\django\contrib\auth\backends.py", line 4, in <module>
    from django.contrib.auth.models import Permission
  File "c:\users\vlab\appdata\local\programs\python\python35\lib\site-packages\django\contrib\auth\models.py", line 4, in <module>
    from django.contrib.auth.base_user import AbstractBaseUser, BaseUserManager
  File "c:\users\vlab\appdata\local\programs\python\python35\lib\site-packages\django\contrib\auth\base_user.py", line 52, in <module>
    class AbstractBaseUser(models.Model):
  File "c:\users\vlab\appdata\local\programs\python\python35\lib\site-packages\django\db\models\base.py", line 110, in __new__
    app_config = apps.get_containing_app_config(module)
  File "c:\users\vlab\appdata\local\programs\python\python35\lib\site-packages\django\apps\registry.py", line 247, in get_containing_app_config
    self.check_apps_ready()
  File "c:\users\vlab\appdata\local\programs\python\python35\lib\site-packages\django\apps\registry.py", line 125, in check_apps_ready
    raise AppRegistryNotReady("Apps aren't loaded yet.")
django.core.exceptions.AppRegistryNotReady: Apps aren't loaded yet.


StdOut: 

StdErr: 
2017-08-30 04:31:17.509859: Unhandled exception in wfastcgi.py: Traceback (most recent call last):
  File "c:\users\vlab\appdata\local\programs\python\python35\lib\site-packages\wfastcgi.py", line 791, in main
    env, handler = read_wsgi_handler(response.physical_path)
  File "c:\users\vlab\appdata\local\programs\python\python35\lib\site-packages\wfastcgi.py", line 633, in read_wsgi_handler
    handler = get_wsgi_handler(os.getenv("WSGI_HANDLER"))
  File "c:\users\vlab\appdata\local\programs\python\python35\lib\site-packages\wfastcgi.py", line 605, in get_wsgi_handler
    handler = handler()
  File "c:\users\vlab\appdata\local\programs\python\python35\lib\site-packages\django\core\handlers\wsgi.py", line 151, in __init__
    self.load_middleware()
  File "c:\users\vlab\appdata\local\programs\python\python35\lib\site-packages\django\core\handlers\base.py", line 80, in load_middleware
    middleware = import_string(middleware_path)
  File "c:\users\vlab\appdata\local\programs\python\python35\lib\site-packages\django\utils\module_loading.py", line 20, in import_string
    module = import_module(module_path)
  File "c:\users\vlab\appdata\local\programs\python\python35\lib\importlib\__init__.py", line 126, in import_module
    return _bootstrap._gcd_import(name[level:], package, level)
  File "<frozen importlib._bootstrap>", line 986, in _gcd_import
  File "<frozen importlib._bootstrap>", line 969, in _find_and_load
  File "<frozen importlib._bootstrap>", line 958, in _find_and_load_unlocked
  File "<frozen importlib._bootstrap>", line 673, in _load_unlocked
  File "<frozen importlib._bootstrap_external>", line 673, in exec_module
  File "<frozen importlib._bootstrap>", line 222, in _call_with_frames_removed
  File "c:\users\vlab\appdata\local\programs\python\python35\lib\site-packages\django\contrib\auth\middleware.py", line 4, in <module>
    from django.contrib.auth.backends import RemoteUserBackend
  File "c:\users\vlab\appdata\local\programs\python\python35\lib\site-packages\django\contrib\auth\backends.py", line 4, in <module>
    from django.contrib.auth.models import Permission
  File "c:\users\vlab\appdata\local\programs\python\python35\lib\site-packages\django\contrib\auth\models.py", line 4, in <module>
    from django.contrib.auth.base_user import AbstractBaseUser, BaseUserManager
  File "c:\users\vlab\appdata\local\programs\python\python35\lib\site-packages\django\contrib\auth\base_user.py", line 52, in <module>
    class AbstractBaseUser(models.Model):
  File "c:\users\vlab\appdata\local\programs\python\python35\lib\site-packages\django\db\models\base.py", line 110, in __new__
    app_config = apps.get_containing_app_config(module)
  File "c:\users\vlab\appdata\local\programs\python\python35\lib\site-packages\django\apps\registry.py", line 247, in get_containing_app_config
    self.check_apps_ready()
  File "c:\users\vlab\appdata\local\programs\python\python35\lib\site-packages\django\apps\registry.py", line 125, in check_apps_ready
    raise AppRegistryNotReady("Apps aren't loaded yet.")
django.core.exceptions.AppRegistryNotReady: Apps aren't loaded yet.
2017-08-30 04:31:17.516878: Running on_exit tasks
2017-08-30 04:31:17.521891: wfastcgi.py 3.0.0 closed
2017-08-30 04:36:44.810657: Error occurred while reading WSGI handler:

Traceback (most recent call last):
  File "c:\users\vlab\appdata\local\programs\python\python35\lib\site-packages\wfastcgi.py", line 791, in main
    env, handler = read_wsgi_handler(response.physical_path)
  File "c:\users\vlab\appdata\local\programs\python\python35\lib\site-packages\wfastcgi.py", line 633, in read_wsgi_handler
    handler = get_wsgi_handler(os.getenv("WSGI_HANDLER"))
  File "c:\users\vlab\appdata\local\programs\python\python35\lib\site-packages\wfastcgi.py", line 616, in get_wsgi_handler
    raise ValueError('"%s" could not be imported%s' % (handler_name, last_tb))
ValueError: "C:\Users\vlab\Desktop\GPA_Server\GPAv2\wsgi.py" could not be imported: Traceback (most recent call last):
  File "c:\users\vlab\appdata\local\programs\python\python35\lib\site-packages\wfastcgi.py", line 600, in get_wsgi_handler
    handler = __import__(module_name, fromlist=[name_list[0][0]])
ImportError: No module named 'C:\\Users\\vlab\\Desktop\\GPA_Server\\GPAv2\\wsgi'



StdOut: 

StdErr: 
2017-08-30 04:36:44.815559: Unhandled exception in wfastcgi.py: Traceback (most recent call last):
  File "c:\users\vlab\appdata\local\programs\python\python35\lib\site-packages\wfastcgi.py", line 791, in main
    env, handler = read_wsgi_handler(response.physical_path)
  File "c:\users\vlab\appdata\local\programs\python\python35\lib\site-packages\wfastcgi.py", line 633, in read_wsgi_handler
    handler = get_wsgi_handler(os.getenv("WSGI_HANDLER"))
  File "c:\users\vlab\appdata\local\programs\python\python35\lib\site-packages\wfastcgi.py", line 616, in get_wsgi_handler
    raise ValueError('"%s" could not be imported%s' % (handler_name, last_tb))
ValueError: "C:\Users\vlab\Desktop\GPA_Server\GPAv2\wsgi.py" could not be imported: Traceback (most recent call last):
  File "c:\users\vlab\appdata\local\programs\python\python35\lib\site-packages\wfastcgi.py", line 600, in get_wsgi_handler
    handler = __import__(module_name, fromlist=[name_list[0][0]])
ImportError: No module named 'C:\\Users\\vlab\\Desktop\\GPA_Server\\GPAv2\\wsgi'

2017-08-30 04:36:44.822579: Running on_exit tasks
2017-08-30 04:36:44.827593: wfastcgi.py 3.0.0 closed
2017-08-30 04:37:05.008462: Error occurred while reading WSGI handler:

Traceback (most recent call last):
  File "c:\users\vlab\appdata\local\programs\python\python35\lib\site-packages\wfastcgi.py", line 791, in main
    env, handler = read_wsgi_handler(response.physical_path)
  File "c:\users\vlab\appdata\local\programs\python\python35\lib\site-packages\wfastcgi.py", line 633, in read_wsgi_handler
    handler = get_wsgi_handler(os.getenv("WSGI_HANDLER"))
  File "c:\users\vlab\appdata\local\programs\python\python35\lib\site-packages\wfastcgi.py", line 605, in get_wsgi_handler
    handler = handler()
  File "c:\users\vlab\appdata\local\programs\python\python35\lib\site-packages\django\core\handlers\wsgi.py", line 151, in __init__
    self.load_middleware()
  File "c:\users\vlab\appdata\local\programs\python\python35\lib\site-packages\django\core\handlers\base.py", line 80, in load_middleware
    middleware = import_string(middleware_path)
  File "c:\users\vlab\appdata\local\programs\python\python35\lib\site-packages\django\utils\module_loading.py", line 20, in import_string
    module = import_module(module_path)
  File "c:\users\vlab\appdata\local\programs\python\python35\lib\importlib\__init__.py", line 126, in import_module
    return _bootstrap._gcd_import(name[level:], package, level)
  File "<frozen importlib._bootstrap>", line 986, in _gcd_import
  File "<frozen importlib._bootstrap>", line 969, in _find_and_load
  File "<frozen importlib._bootstrap>", line 958, in _find_and_load_unlocked
  File "<frozen importlib._bootstrap>", line 673, in _load_unlocked
  File "<frozen importlib._bootstrap_external>", line 673, in exec_module
  File "<frozen importlib._bootstrap>", line 222, in _call_with_frames_removed
  File "c:\users\vlab\appdata\local\programs\python\python35\lib\site-packages\django\contrib\auth\middleware.py", line 4, in <module>
    from django.contrib.auth.backends import RemoteUserBackend
  File "c:\users\vlab\appdata\local\programs\python\python35\lib\site-packages\django\contrib\auth\backends.py", line 4, in <module>
    from django.contrib.auth.models import Permission
  File "c:\users\vlab\appdata\local\programs\python\python35\lib\site-packages\django\contrib\auth\models.py", line 4, in <module>
    from django.contrib.auth.base_user import AbstractBaseUser, BaseUserManager
  File "c:\users\vlab\appdata\local\programs\python\python35\lib\site-packages\django\contrib\auth\base_user.py", line 52, in <module>
    class AbstractBaseUser(models.Model):
  File "c:\users\vlab\appdata\local\programs\python\python35\lib\site-packages\django\db\models\base.py", line 110, in __new__
    app_config = apps.get_containing_app_config(module)
  File "c:\users\vlab\appdata\local\programs\python\python35\lib\site-packages\django\apps\registry.py", line 247, in get_containing_app_config
    self.check_apps_ready()
  File "c:\users\vlab\appdata\local\programs\python\python35\lib\site-packages\django\apps\registry.py", line 125, in check_apps_ready
    raise AppRegistryNotReady("Apps aren't loaded yet.")
django.core.exceptions.AppRegistryNotReady: Apps aren't loaded yet.


StdOut: 

StdErr: 
2017-08-30 04:37:05.013476: Unhandled exception in wfastcgi.py: Traceback (most recent call last):
  File "c:\users\vlab\appdata\local\programs\python\python35\lib\site-packages\wfastcgi.py", line 791, in main
    env, handler = read_wsgi_handler(response.physical_path)
  File "c:\users\vlab\appdata\local\programs\python\python35\lib\site-packages\wfastcgi.py", line 633, in read_wsgi_handler
    handler = get_wsgi_handler(os.getenv("WSGI_HANDLER"))
  File "c:\users\vlab\appdata\local\programs\python\python35\lib\site-packages\wfastcgi.py", line 605, in get_wsgi_handler
    handler = handler()
  File "c:\users\vlab\appdata\local\programs\python\python35\lib\site-packages\django\core\handlers\wsgi.py", line 151, in __init__
    self.load_middleware()
  File "c:\users\vlab\appdata\local\programs\python\python35\lib\site-packages\django\core\handlers\base.py", line 80, in load_middleware
    middleware = import_string(middleware_path)
  File "c:\users\vlab\appdata\local\programs\python\python35\lib\site-packages\django\utils\module_loading.py", line 20, in import_string
    module = import_module(module_path)
  File "c:\users\vlab\appdata\local\programs\python\python35\lib\importlib\__init__.py", line 126, in import_module
    return _bootstrap._gcd_import(name[level:], package, level)
  File "<frozen importlib._bootstrap>", line 986, in _gcd_import
  File "<frozen importlib._bootstrap>", line 969, in _find_and_load
  File "<frozen importlib._bootstrap>", line 958, in _find_and_load_unlocked
  File "<frozen importlib._bootstrap>", line 673, in _load_unlocked
  File "<frozen importlib._bootstrap_external>", line 673, in exec_module
  File "<frozen importlib._bootstrap>", line 222, in _call_with_frames_removed
  File "c:\users\vlab\appdata\local\programs\python\python35\lib\site-packages\django\contrib\auth\middleware.py", line 4, in <module>
    from django.contrib.auth.backends import RemoteUserBackend
  File "c:\users\vlab\appdata\local\programs\python\python35\lib\site-packages\django\contrib\auth\backends.py", line 4, in <module>
    from django.contrib.auth.models import Permission
  File "c:\users\vlab\appdata\local\programs\python\python35\lib\site-packages\django\contrib\auth\models.py", line 4, in <module>
    from django.contrib.auth.base_user import AbstractBaseUser, BaseUserManager
  File "c:\users\vlab\appdata\local\programs\python\python35\lib\site-packages\django\contrib\auth\base_user.py", line 52, in <module>
    class AbstractBaseUser(models.Model):
  File "c:\users\vlab\appdata\local\programs\python\python35\lib\site-packages\django\db\models\base.py", line 110, in __new__
    app_config = apps.get_containing_app_config(module)
  File "c:\users\vlab\appdata\local\programs\python\python35\lib\site-packages\django\apps\registry.py", line 247, in get_containing_app_config
    self.check_apps_ready()
  File "c:\users\vlab\appdata\local\programs\python\python35\lib\site-packages\django\apps\registry.py", line 125, in check_apps_ready
    raise AppRegistryNotReady("Apps aren't loaded yet.")
django.core.exceptions.AppRegistryNotReady: Apps aren't loaded yet.
2017-08-30 04:37:05.018490: Running on_exit tasks
2017-08-30 04:37:05.024507: wfastcgi.py 3.0.0 closed
2017-08-30 04:40:03.396503: wfastcgi.py will restart when files in C:\Users\vlab\Desktop\GPA_Server\ are changed: .*((\.py)|(\.config))$
2017-08-30 04:40:03.401516: wfastcgi.py 3.0.0 initialized
2017-08-30 04:45:17.811175: Unhandled exception in wfastcgi.py: Traceback (most recent call last):
  File "c:\users\vlab\appdata\local\programs\python\python35\lib\site-packages\wfastcgi.py", line 774, in main
    record = read_fastcgi_record(fcgi_stream)
  File "c:\users\vlab\appdata\local\programs\python\python35\lib\site-packages\wfastcgi.py", line 158, in read_fastcgi_record
    data = stream.read(8)     # read record
OSError: [Errno 22] Invalid argument
2017-08-30 04:45:17.819197: Running on_exit tasks
2017-08-30 04:45:17.827218: wfastcgi.py 3.0.0 closed
2017-08-30 04:50:01.787469: wfastcgi.py will restart when files in C:\Users\vlab\Desktop\GPA_Server\ are changed: .*((\.py)|(\.config))$
2017-08-30 04:50:01.792483: wfastcgi.py 3.0.0 initialized
2017-08-30 04:52:51.910997: wfastcgi.py will restart when files in C:\Users\vlab\Desktop\GPA_Server\ are changed: .*((\.py)|(\.config))$
2017-08-30 04:52:51.915978: wfastcgi.py 3.0.0 initialized
2017-08-30 04:57:24.513832: wfastcgi.py will restart when files in C:\Users\vlab\Desktop\GPA_Server\ are changed: .*((\.py)|(\.config))$
2017-08-30 04:57:24.517831: wfastcgi.py 3.0.0 initialized
2017-08-30 04:57:56.517275: wfastcgi.py will restart when files in C:\Users\vlab\Desktop\GPA_Server\ are changed: .*((\.py)|(\.config))$
2017-08-30 04:57:56.525275: wfastcgi.py 3.0.0 initialized
2017-08-30 04:58:27.989198: wfastcgi.py exiting because GPAv2\settings.py has changed, matching .*((\.py)|(\.config))$
2017-08-30 04:58:27.993198: wfastcgi.py exiting because GPAv2\settings.py has changed, matching .*((\.py)|(\.config))$
2017-08-30 04:58:27.993198: Running on_exit tasks
2017-08-30 04:58:28.005198: Running on_exit tasks
2017-08-30 04:59:16.047443: wfastcgi.py will restart when files in C:\Users\vlab\Desktop\GPA_Server\ are changed: .*((\.py)|(\.config))$
2017-08-30 04:59:16.051446: wfastcgi.py 3.0.0 initialized
2017-08-30 04:59:37.143392: wfastcgi.py will restart when files in C:\Users\vlab\Desktop\GPA_Server\ are changed: .*((\.py)|(\.config))$
2017-08-30 04:59:37.147390: wfastcgi.py 3.0.0 initialized
2017-08-30 12:51:39.395001: wfastcgi.py will restart when files in C:\Users\vlab\Desktop\GPA_Server\ are changed: .*((\.py)|(\.config))$
2017-08-30 12:51:39.398998: wfastcgi.py 3.0.0 initialized
2017-08-30 13:07:45.526941: wfastcgi.py exiting because GPA\Excel.py has changed, matching .*((\.py)|(\.config))$
2017-08-30 13:07:45.526941: Running on_exit tasks
